Workbook
Name \A: #REF!
Name \B: #REF!
Name \C: #REF!
Name _\A: #REF!
Name _\B: #REF!
Name _\C: #REF!
Name _________________R: [1]AN2!#REF!
Name ________________R: [1]AN2!#REF!
Name ________________RR: [1]AN2!#REF!
Name _______________R: [1]AN2!#REF!
Name _____________R: [1]AN2!#REF!
Name ____________R: [1]AN2!#REF!
Name ___________R: [1]AN2!#REF!
Name __________R: [1]AN2!#REF!
Name _________R: [1]AN2!#REF!
Name ________R: [1]AN2!#REF!
Name _______R: [1]AN2!#REF!
Name ______R: [1]AN2!#REF!
Name _____R: [1]AN2!#REF!
Name ____R: [1]AN2!#REF!
Name ___R: [1]AN2!#REF!
Name __R: [1]AN2!#REF!
Name __tx1: #N/A
Name __tx2: #N/A
Name _01_aoû_87: #REF!
Name _01_aoû_88: #REF!
Name _01_aoû_89: #REF!
Name _01_aoû_90: #REF!
Name _01_aoû_91: #REF!
Name _01_aoû_92: #REF!
Name _01_aoû_93: #REF!
Name _01_aoû_94: #REF!
Name _01_aoû_95: #REF!
Name _01_aoû_96: #REF!
Name _01_aoû_97: #REF!
Name _01_avr_87: #REF!
Name _01_avr_88: #REF!
Name _01_avr_89: #REF!
Name _01_avr_90: #REF!
Name _01_avr_91: #REF!
Name _01_avr_92: #REF!
Name _01_avr_93: #REF!
Name _01_avr_94: #REF!
Name _01_avr_95: #REF!
Name _01_avr_96: #REF!
Name _01_avr_97: #REF!
Name _01_déc_87: #REF!
Name _01_déc_88: #REF!
Name _01_déc_89: #REF!
Name _01_déc_90: #REF!
Name _01_déc_91: #REF!
Name _01_déc_92: #REF!
Name _01_déc_93: #REF!
Name _01_déc_94: #REF!
Name _01_déc_95: #REF!
Name _01_déc_96: #REF!
Name _01_déc_97: #REF!
Name _01_fév_87: #REF!
Name _01_fév_88: #REF!
Name _01_fév_89: #REF!

Sheet Recap Generale 
B4: Affaire :
B5: Construction d’une ferme expérimentale - ITX BENGUERIR
B7: Date: 16/02/2026
B9: Maître d'ouvrage : ITX
B11: Liste des lots : | C11: Montant HT en MAD | D11: TVA | E11: Montant TVA en MAD | F11: Montant TTC en MAD
B12: TOTAL LOT N° 01 GROS ŒUVRE | C12: =+'Lot N°01 GROS OEUVRE '!G127 -> 0 | D12: 0.2 | E12: =+C12*20% -> 0 | F12: =+C12+E12 -> 0
B13: TOTAL LOT N° 02 ETANCHEITE | C13: =+'Lot N°02 ETANCHEITE'!G16 -> 0 | D13: 0.2 | E13: =+C13*20% -> 0 | F13: =+C13+E13 -> 0
B14: TOTAL LOT N° 03 CHARPENTE METALLIQUE | C14: =+'Lot N03 CHARPENTE METALLIQUE '!G24 -> 0 | D14: 0.2 | E14: =+C14*20% -> 0 | F14: =+C14+E14 -> 0
B15: TOTAL LOT N° 04 FLUIDES | C15: =+'Lot N°04 FLUIDES'!G344 -> 0 | D15: 0.2 | E15: =+C15*20% -> 0 | F15: =+C15+E15 -> 0
B16: TOTAL LOT N° 05 ELECTRICITE CFO-CFA | C16: =+'Lot N° 05 ELECTRICITE'!G253 -> 0 | D16: 0.2 | E16: =+C16*20% -> 0 | F16: =+C16+E16 -> 0
B17: TOTAL LOT N° 06 REVETEMENT | C17: =+'Lot N° 06 REVETEMENT'!G31 -> 0 | D17: 0.2 | E17: =+C17*20% -> 0 | F17: =+C17+E17 -> 0
B18: TOTAL LOT N° 07 MENUISERIE BOIS | C18: =+'Lot N° 07 MENUISERIE BOIS'!G16 -> 0 | D18: 0.2 | E18: =+C18*20% -> 0 | F18: =+C18+E18 -> 0
B19: TOTALLOT N° 08 MENUISERIE ALUMINIUM | C19: =+'Lot N° 08 MENUISERIE ALUM'!G19 -> 0 | D19: 0.2 | E19: =+C19*20% -> 0 | F19: =+C19+E19 -> 0
B20: TOTAL LOT N° 09 MENUISERIE METALLIQUE | C20: =+'Lot N° 09 MENUISERIE METAL'!G51 -> 0 | D20: 0.2 | E20: =+C20*20% -> 0 | F20: =+C20+E20 -> 0
B21: TOTAL LOT N° 10 FAUX PLAFOND | C21: =+'Lot N°10 FAUX PLAFOND'!G13 -> 0 | D21: 0.2 | E21: =+C21*20% -> 0 | F21: =+C21+E21 -> 0
B22: TOTAL LOT N° 11 PEINTURE | C22: =+'Lot N°11 PEINTURE'!G21 -> 0 | D22: 0.2 | E22: =+C22*20% -> 0 | F22: =+C22+E22 -> 0
B23: Total : | C23: =SUM(C12:C22) -> 0 | E23: =SUM(E12:E22) -> 0 | F23: =SUM(F12:F22) -> 0

Sheet Lot N°01 GROS OEUVRE 
B2: DESIGNATION DES PRESTATIONS | C2: U | D2: Quantité | E2: Prix unitaires en chiffres en MAD | F2: Prix unitaires en lettres MAD | G2: Total H.T en MAD
B4: GROS OEUVRE
A5: 01.1 | B5: TERRASSEMENT
A7: 01.1.1 | B7: Décapage de la terre végétale de 40 cm y/c évacuation | ZL7: CH4
B8: Le mètre carré | C8: M² | D8: 4185 | G8: =D8*E8 -> 0
A9: 01.1.2 | B9: Fouilles en rigoles ou en tranchées ou en puits dans tout terrain y/c rocher
B10: Pour fouilles en puits | C10: M3 | D10: 650 | G10: =D10*E10 -> 0
B11: Le mètre cube
B12: Pour fouilles en rigole | C12: M3 | D12: 66 | G12: =D12*E12 -> 0
B13: Le mètre cube
A14: 01.1.3 | B14: Remblaiement ou évacuation aux décharges publiques | C14: M3 | D14: =+D12+D10 -> 716 | G14: =D14*E14 -> 0
B15: Le mètre cube
B17: Total TERRASSEMENT | G17: =SUM(G5:G15) -> 0
A19: 01.2 | B19: MACONNERIE EN FONDATIONS
A20: 01.2.1 | B20: Béton de propreté de 10 cm
B21: Le mètre cube | C21: M3 | D21: 100 | G21: =D21*E21 -> 0
B23: Total MACONNERIE EN FONDATIONS | G23: =SUM(G19:G21) -> 0
A25: 01.3 | B25: BETON EN FONDATIONS POUR TOUT OUVRAGE
A26: 01.3.1 | B26: Béton pour tout ouvrage en fondations
B27: Pour semelles isolées | C27: M3 | D27: 380 | G27: =D27*E27 -> 0
B28: Le mètre cube
B29: Pour fût de poteaux | C29: M3 | D29: 28 | G29: =D29*E29 -> 0
B30: Le mètre cube
B31: Pour longrines | C31: M3 | D31: 75 | G31: =D31*E31 -> 0
B32: Le mètre cube
A33: 01.3.2 | B33: Armatures en aciers HA en fondations
B34: Le Kilogramme | C34: Kg | D34: 36405 | G34: =D34*E34 -> 0
B36: Total BETON EN FONDATIONS POUR TOUT OUVRAGE | G36: =SUM(G25:G35) -> 0
A38: 01.4 | B38: RESEAU D'ASSANISSEMENT ET OUVRAGES ANNEXES
A39: 01.4.1 | B39: Canalisations en PVC pour évacuations
B40: Pour buse de diamètre 200 mm | C40: ML | D40: 300 | G40: =D40*E40 -> 0
B41: Le mètre linéaire
B42: Pour buse de diamètre 300 mm | C42: ML | D42: 250 | G42: =D42*E42 -> 0
B43: Le mètre linéaire
A44: 01.4.2 | B44: Regards pour évacuation
B45: Regard 60x60 cm visitable | C45: U | D45: 10 | G45: =D45*E45 -> 0
B46: L'unité
B47: Regard 60x60 cm non visitable | C47: U | D47: 5 | G47: =D47*E47 -> 0
B48: L'unité
A49: 01.4.3 | B49: Mise a la terre
...

Sheet Lot N°02 ETANCHEITE
B2: DESIGNATION DES PRESTATIONS | C2: U | D2: Quantité | E2: Prix unitaires en chiffres en MAD | F2: Prix unitaires en lettres | G2: Total H.T en MAD
B4: LOT N°02 / ETANCHEITE | ZL4: CH2 | ZM4: ETANC
A5: 02.1 | B5: ETANCHEITE SUR SUPPORT BETON | ZL5: CH3
A7: 02.1.1 | B7: Étanchéité légère des salles d’eau | C7: M² | D7: 140 | G7: =+E7*D7 -> 0 | ZL7: ART | ZM7: 000-A136
B8: Le mètre carré
A10: 02.2 | B10: DIVERS
A11: 02.2.1 | B11: Entrée d'eau pluviale diamètre 200 mm | C11: U | D11: 10 | G11: =+E11*D11 -> 0
B12: L'unité
B14: Total ETANCHEITE SUR SUPPORT BETON | G14: =SUM(G4:G12) -> 0 | ZL14: STOT
B16: Montant HT du Lot N°02 ETANCHEITE | G16: =+G14 -> 0 | ZL16: TOTHT
B17: =CONCATENATE("TVA (",'[46]Recap Generale'!D14,"%)") -> TVA (20%) | G17: =+G16*20% -> 0 | ZL17: TVA
B18: Montant TTC | G18: =+G17+G16 -> 0 | ZL18: TOTTTC

Sheet Lot N03 CHARPENTE METALLIQUE 
B2: DESIGNATION DES PRESTATIONS | C2: U | D2: QUANTITE | E2: Prix unitaires en chiffres en MAD | F2: Prix unitaires en lettres en MAD | G2: Total Global H.T en MAD
A4: 03.1 | B4: CHARPENTE METALLIQUE | ZP4: CH2 | ZQ4: ETANC
A5: 03.1.1 | B5: Structure métallique galvanisé à chaud y/c peinture en polyuréthane | ZP5: CH4
B6: Le kilogramme | C6: Kg | D6: 102040 | G6: =+D6*E6 -> 0 | ZP6: ART | ZQ6: 000-A128
A7: 03.1.2 | B7: Couverture en tôle Toitesco y/c peinture
B8: Le mètre carré | C8: M² | D8: 2560 | G8: =+D8*E8 -> 0 | ZP8: CH4
A9: 03.1.3 | B9: Couverture en auto portantes
B10: Le mètre carré | C10: M² | D10: 720 | G10: =+D10*E10 -> 0 | ZP10: CH4
A11: 03.1.4 | B11: Fourniture et pose des platine métalliques | ZP11: ART | ZQ11: 000-A129
B12: L`unité | C12: U | D12: 84 | G12: =+D12*E12 -> 0
A13: 03.1.5 | B13: Descente d`eau pluviale en PVC diamètre 200 mm | ZP13: CH4
B14: Le mètre linéaire | C14: ML | D14: 102 | G14: =+D14*E14 -> 0 | ZP14: ART | ZQ14: 000-A130
A15: 03.1.6 | B15: Gargouille en plomb pour tous diamètres
B16: L`unité | C16: U | D16: 15 | G16: =+D16*E16 -> 0 | ZP16: CH4
A17: 03.1.7 | B17: Chêneau en tôle galvanisée y/c étanchéité | ZP17: ART | ZQ17: 000-A141
B18: Le mètre linéaire | C18: ML | D18: 205 | G18: =+D18*E18 -> 0
A19: 03.1.8 | B19: Étanchéité pour structure métallique y/c isolation
B20: Le mètre carré | C20: M² | D20: 3280 | G20: =+D20*E20 -> 0 | ZP20: CH4
B22: TOTAL CHARPENTE METALLIQUE | G22: =+SUM(G6:G21) -> 0 | ZP22: STOT
B24: Montant HT du Lot N°03 CHARPENTE METALLIQUE | G24: =+G22 -> 0 | ZP24: TOTHT
B25: =CONCATENATE("TVA (",'[46]Recap Generale'!D14,"%)") -> TVA (20%) | G25: =G24*20% -> 0 | ZP25: TVA
B26: Montant TTC | G26: =+G25+G24 -> 0 | ZP26: TOTTTC

Sheet Lot N°04 FLUIDES
A3: N° | B3: Désignations des ouvrages | C3: U | D3: QUANTITE FERME EXPERIMENTALE | E3: P.U. HT en chiffres | F3: P.U. HT en lettres | G3: TOTAL. HT
A5: 4.1 | B5: RESEAUX D'EAU FROIDE ET EAU CHAUDE SANITAIRE
A8: 4.1.1 | B8: BÂCHES EN PEHD ACS DE 15 M³ POUR EAU POTABLE ET INCENDIE
B9: l'ensemble | C9: E | D9: 2 | G9: =+D9*E9 -> 0
A11: 4.1.2 | B11: GROUPE DE SURPRESSION EAU FROIDE
B12: l'ensemble | C12: E | D12: 1 | G12: =+D12*E12 -> 0
A14: 4.1.3 | B14: TRAITEMENT D'EAU POTABLE
A15: a | B15: Filtre autonettoyant automatique
B16: l'ensemble | C16: E | D16: 1 | G16: =+D16*E16 -> 0
A18: 4.1.4 | B18: SOUS COMPTEUR D'EAU
B19: l'ensemble | C19: E | D19: 6 | G19: =+D19*E19 -> 0
A21: 4.1.5 | B21: CANALISATION EAU POTABLE EN POLYPROPYLENE PN 20
A22: a | B22: diamètre 20x3.4 (Int 13) à diamètre 32x 5.4 (Int 20)
B23: le mètre linéaire | C23: ML | D23: 480 | G23: =+D23*E23 -> 0
A24: b | B24: diamètre 40 x 6.7 (Int 25) à 50 x 8.3 (Int 32)
B25: le mètre linéaire | C25: ML | D25: 350 | G25: =+D25*E25 -> 0
A26: c | B26: diamètre 63 x 10.5 (Int 42)à diamètre 75 x 12.5 (Int 50)
B27: le mètre linéaire | C27: ML | D27: 100 | G27: =+D27*E27 -> 0
A28: d | B28: DN 100 à DN 125
B29: le mètre linéaire | C29: ML | D29: PM | G29: PM
A31: 4.1.6 | B31: CALORIFUGE EN CAOUTCHOUC SYNTHETIQUE
B32: le mètre linéaire | C32: ML | D32: 100 | G32: =+D32*E32 -> 0
A34: 4.1.7 | B34: TUYAU EN POLYETHYLENE RETICULE POUR DISTRIBUTION SECONDAIRE
A35: a | B35: Douche
B36: l'unité | C36: U | D36: PM | G36: PM
A37: b | B37: Eviers
B38: l'unité | C38: U | D38: PM | G38: PM
A39: 4.1.8 | B39: ROBINET DE PUISAGE
B40: l'unité | C40: U | D40: 2 | G40: =+D40*E40 -> 0
A42: 4.1.9 | B42: MITIGEUR THERMOSTATIQUE
B43: l'unité | C43: U | D43: 4 | G43: =+D43*E43 -> 0
A45: 4.1.10 | B45: BOUCHE D’ARROSAGE
B46: l'ensemble | C46: E | D46: PM | G46: PM
A48: 4.1.11 | B48: CHAUFFE-EAU ELECTRIQUE
A49: a | B49: Capacité 100 litres
B50: l'unité | C50: U | D50: 4 | G50: =+D50*E50 -> 0
B52: TOTAL H.T / RESEAUX D'EAU FROIDE ET EAU CHAUDE SANITAIRE | G52: =SUM(G7:G51) -> 0
A54: 4.2 | B54: EVACUATION DES EAUX USEES -
B55: EAUX PLUVIALES - EAUX VANNES
A57: 4.2.1 | B57: CHUTES ET COLLECTEURS EN PVC POUR EU - EV – EP
...

Sheet Lot N° 05 ELECTRICITE
B3: DESIGNATION DES PRESTATIONS | C3: U | D3: QTE BIO TECH | E3: Prix unitaires en chiffres en MAD | F3: Prix unitaires en lettres en MAD | G3: Total H.T en MAD
A4: 5 | B4: LOT ELECTRICITE
A6: 5.1 | B6: LOT ELECTRICITE CFO
A7: 5.1.1 | B7: ARMOIRES GENERALES DE PROTECTION
A8: a | B8: Armoire AGP
B9: L'UNITE : | C9: U | D9: 1 | G9: =D9*E9 -> 0
A10: b | B10: Liaison BT AGP/TGBT
B11: LE METRE LINEAIRE : | C11: Ens | D11: 1 | G11: =D11*E11 -> 0
A12: 5.1.2 | B12: ARMOIRES TGBT, AIS ET ACA
A13: a | B13: Armoire TGBT-N
B14: L'UNITE : | C14: U | D14: 1 | G14: =D14*E14 -> 0
A15: b | B15: Armoire ACA
B16: L'UNITE : | C16: U | D16: 1 | G16: =D16*E16 -> 0
A17: 5.1.3 | B17: ARMOIRES ET COFFRETS DE PROTECTION
A18: a | B18: Armoire de protection Ecl & Force
B19: L'UNITE : | C19: U | D19: 6 | G19: =D19*E19 -> 0
A20: b | B20: TE POULE PONDEUDE
B21: L'UNITE : | C21: U | D21: 1 | G21: =D21*E21 -> 0
A22: c | B22: TE POULE DE CHAIR
B23: L'UNITE : | C23: U | D23: 1 | G23: =D23*E23 -> 0
A24: d | B24: TE POULE DE CHAIR BIS
B25: L'UNITE : | C25: U | D25: 1 | G25: =D25*E25 -> 0
A26: e | B26: TE UNITE ELEVAGE PORCINE
B27: L'UNITE : | C27: U | D27: 1 | G27: =D27*E27 -> 0
A28: f | B28: TE UNITE ELEVAGE PORCINE BIS
B29: L'UNITE : | C29: U | D29: 1 | G29: =D29*E29 -> 0
A30: g | B30: TE UNITE BOVIN
B31: L'UNITE : | C31: U | D31: 1 | G31: =D31*E31 -> 0
A32: h | B32: TE UNITE BOVIN BIS
B33: L'UNITE : | C33: U | D33: 1 | G33: =D33*E33 -> 0
A34: 5.1.4 | B34: CABLES DE DISTRIBUTION
A35: a | B35: U 1000 RO2V 1x240 mm2
B36: LE METRE LINEAIRE : | C36: ML | D36: 100 | G36: =D36*E36 -> 0
A37: b | B37: U 1000 RO2V 1x150 mm2
B38: LE METRE LINEAIRE : | C38: ML | D38: 400 | G38: =D38*E38 -> 0
A39: c | B39: U 1000 RO2V 1x120 mm2
B40: LE METRE LINEAIRE : | C40: ML | D40: =580*4 -> 2320 | G40: =D40*E40 -> 0
A41: d | B41: U 1000 RO2V 5G50 mm2
B42: LE METRE LINEAIRE : | C42: ML | D42: 575 | G42: =D42*E42 -> 0
A43: e | B43: U 1000 RO2V 5G10 mm2
...

Sheet Lot N° 06 REVETEMENT
B2: DESIGNATION DES PRESTATIONS | C2: U | D2: QUANTITE | E2: Prix unitaires en chiffres en MAD | F2: Prix unitaires en lettres en MAD | G2: Total Global H.T en MAD
A4: 06 | B4: REVETEMENT
A5: 06.1 | B5: REVETEMENT DE SOL
A7: 06.1.1 | B7: Revêtement de sol en carrelage dimension de 60 x 60 cm
B8: Le mètre carré | C8: M² | D8: 355 | G8: =+D8*E8 -> 0
A9: 06.1.2 | B9: Revêtement de sol en terre battue
B10: Le mètre carré | C10: M² | D10: 565 | G10: =+D10*E10 -> 0
A11: 06.1.3 | B11: Revêtement de sol en béton lisse
B12: Le mètre carré | C12: M² | D12: 2365 | G12: =+D12*E12 -> 0
A13: 06.1.4 | B13: Revêtement de sol en caillebotis sur vide sanitaire
B14: Le mètre carré | C14: M² | D14: 620 | G14: =+D14*E14 -> 0
B16: Total REVETEMENT DE SOL | G16: =SUM(G8:G15) -> 0
A18: 06.2 | B18: REVETEMENT MURAL
A19: 06.2.1 | B19: Revêtement mural en carrelage dimension de 60 x 60 cm
B20: Le mètre carré | C20: M² | D20: 180 | G20: =+D20*E20 -> 0
B22: Total REVETEMENT MURAL | G22: =SUM(G20:G20) -> 0
A24: 06.3 | B24: PLINTHE
A25: 06.3.1 | B25: Plinthe en carrelage de 10 cm
B26: Le mètre linéaire | C26: ML | D26: 320 | G26: =+D26*E26 -> 0
B28: Total PLINTHE | G28: =SUM(G25:G27) -> 0
B31: Montant HT du Lot N°06 REVETEMENT | G31: =+G28+G22+G16 -> 0
B32: =CONCATENATE("TVA (",'[45]Recap Generale'!D12,"%)") -> TVA (20%) | G32: =+G31*0.2 -> 0
B33: Montant TTC | G33: =SUM(G31:G32) -> 0

Sheet Lot N° 07 MENUISERIE BOIS
B2: DESIGNATION DES PRESTATIONS | C2: U | D2: QUANTITE | E2: Prix unitaires en chiffres en MAD | F2: Prix unitaires en lettres en MAD | G2: Total Global H.T en MAD
A4: 07 | B4: MENUISERIE EN BOIS
A6: 07.1 | B6: PORTE ISOPLANE EN BOIS
A8: 07.1.1 | B8: Porte isoplane en bois finition chêne à un vantail ouvrant à la française
B9: Type PB1 dimension de 0,98 x 2,14 m
B10: L'unité | C10: U | D10: 8 | G10: =+D10*E10 -> 0
B11: Type PB2 dimension de 0,78 x 2,14 m
B12: L'unité | C12: U | D12: 6 | G12: =+D12*E12 -> 0
B14: Total PORTE ISOPLANE EN BOIS | G14: =SUM(G7:G13) -> 0
B16: Montant HT du Lot N°07 MENUISERIE EN BOIS | G16: =+G14 -> 0
B17: =CONCATENATE("TVA (",'[45]Recap Generale'!D12,"%)") -> TVA (20%) | G17: =+G16*0.2 -> 0
B18: Montant TTC | G18: =SUM(G16:G17) -> 0

Sheet Lot N° 08 MENUISERIE ALUM
B2: DESIGNATION DES PRESTATIONS | C2: U | D2: QUANTITE | E2: Prix unitaires en chiffres en MAD | F2: Prix unitaires en lettres en MAD | G2: Total Global H.T en MAD
A4: 8 | B4: MENUISERIE EN ALUMINUIM
A6: 08.1 | B6: CHASSIS EN ALUMINUIM
A7: 08.1.1 | B7: Châssis fixe en aluminium
B8: Type F03 dimension de 0,60 m x 0,60m
B9: L'unité | C9: U | D9: 10 | G9: =E9*D9 -> 0
B11: Total CHASSIS EN ALUMINUIM | G11: =SUM(G7:G10) -> 0
A13: 08.2 | B13: PANNEAU SANDWICH EN ALUMINIUM
A14: 08.2.1 | B14: Panneau sandiwich
B15: Le mètre carré | C15: M² | D15: 920 | G15: =+E15*D15 -> 0
B17: Total PANNEAU SANDWICH EN ALUMINIUM | G17: =SUM(G13:G16) -> 0
B19: Montant HT du Lot N°08 MENUISERIE ALUMINIUM | G19: =G11+G17 -> 0
B20: TVA (20%) | G20: =+G19*0.2 -> 0
B21: Montant TTC | G21: =SUM(G19:G20) -> 0 | ZI21: STOT
ZI23: TOTHT
ZI24: TVA
ZI25: TOTTTC

Sheet Lot N° 09 MENUISERIE METAL
B2: DESIGNATION DES PRESTATIONS | C2: U | D2: QUANTITE | E2: Prix unitaires en chiffres en MAD | F2: Prix unitaires en lettres en MAD | G2: Total Global H.T en MAD
A4: 9 | B4: MENUISERIE METALLIQUE
A6: 09.1 | B6: PORTE METALLIQUE OUVRANT A LA FRANCAISE
A7: 09.1.1 | B7: Porte métallique a un vantail à un vantail ouvrant à la française
B8: Type PM04 dimension de 0,88 x 2,24 m
B9: L'unité | C9: U | D9: 2 | G9: =+D9*E9 -> 0
B10: Type PM05 dimension de 0,98 x 2,24 m
B11: L'unité | C11: U | D11: 49 | G11: =+D11*E11 -> 0
B12: Type PM06 dimension de 1,18 x 2,24 m
B13: L'unité | C13: U | D13: 3 | G13: =+D13*E13 -> 0
A14: 09.1.2 | B14: Porte métallique a deux vanteaux ouvrant à la française
B15: Type PM01 dimension de 1,60 x 2,20 m
B16: L'unité | C16: U | D16: 17 | G16: =+D16*E16 -> 0
B17: Type PM02 dimension de 1,80 x 2,20 m
B18: L'unité | C18: U | D18: 3 | G18: =+D18*E18 -> 0
B19: Type PM03 dimension de 2,20 x 2,20 m
B20: L'unité | C20: U | D20: 2 | G20: =+D20*E20 -> 0
B22: Total CORNADIS EN METALLIQUE | G22: =SUM(G8:G20) -> 0
A24: 09.2 | B24: PORTE METALLIQUE GRILLAGEE
A25: 09.2.1 | B25: Porte métallique grillagé à deux vantaux ouvrant à la française
B26: Type PMG1 dimension de 3,00 x 3,00 m
B27: L'unité | C27: U | D27: 4 | G27: =+D27*E27 -> 0
B28: Type PMG02 dimension de 1,60 x 2,20 m
B29: L'unité | C29: U | D29: 2 | G29: =+D29*E29 -> 0
B30: Type PMG03 dimension de 1,80 x 1,50 m
B31: L'unité | C31: U | D31: 10 | G31: =+D31*E31 -> 0
B32: Type PMG04 dimension de 1,20 x 1,20 m
B33: L'unité | C33: U | D33: 12 | G33: =+D33*E33 -> 0
B35: Total PORTE METALLIQUE OUVRANTS | G35: =SUM(G26:G33) -> 0
A37: 09.3 | B37: CORNADIS EN METALLIQUE
A38: 09.3.1 | B38: Cornadis métallique dimension de 2,50 x 1,50 m
B39: Le mètre carré | C39: M² | D39: 14 | G39: =+D39*E39 -> 0
B41: Total CORNADIS EN METALLIQUE | G41: =SUM(G38:G39) -> 0
A43: 09.4 | B43: MUR GRILLAGE
A44: 09.4.1 | B44: Mur grillage de 1,50 m
B45: Le mètre carré | C45: M² | D45: 260 | G45: =+E45*D45 -> 0
A46: 09.4.2 | B46: Mur grillage de 3,00m
B47: Le mètre carré | C47: M² | D47: 300 | G47: =+E47*D47 -> 0
B49: Total MUR GRILLAGE | G49: =SUM(G44:G48) -> 0
A51: Montant HT du Lot N°09 MENUISERIE METALLIQUE | G51: =+G41+G35+G49 -> 0
...

Sheet Lot N°10 FAUX PLAFOND
B2: DESIGNATION DES PRESTATIONS | C2: U | D2: QUANTITE | E2: Prix unitaires en chiffres en MAD | F2: Prix unitaires en lettres en MAD | G2: Total Global H.T en MAD
A4: 010 | B4: FAUX PLAFOND
A6: 10.1 | B6: FAUX PLAFOND EN BA13
A8: 10.1.1 | B8: Faux plafond BA13 hydrofuge
B9: Le mètre carré | C9: M² | D9: 55 | G9: =+D9*E9 -> 0
B11: Total FAUX PLAFOND EN BA13 | G11: =SUM(G8:G10) -> 0
B13: Montant HT du Lot N°10 FAUX PLAFOND | G13: =+G11 -> 0
B14: =CONCATENATE("TVA (",'[45]Recap Generale'!D12,"%)") -> TVA (20%) | G14: =+G13*0.2 -> 0
B15: Montant TTC | G15: =SUM(G13:G14) -> 0

Sheet Lot N°11 PEINTURE
B2: DESIGNATION DES PRESTATIONS | C2: U | D2: QUANTITE | E2: Prix unitaires en chiffres en MAD | F2: Prix unitaires en lettres en MAD | G2: Total Global H.T en MAD
A4: 11 | B4: PEINTURE
A6: 11.1 | B6: PEINTURE EXTERIEURE
A7: 11.1.1 | B7: Peinture ocre sur façades extérieures
B8: Le mètre carre | C8: M2 | D8: 1380 | G8: =+D8*E8 -> 0
B10: Total PEINTURE EXTERIEURE | G10: =SUM(G7:G9) -> 0
A12: 11.2 | B12: PEINTURE INTERIEURE
A13: 11.2.1 | B13: Peinture vinylique intérieure
B14: Peinture vinylique sur murs
B15: Le mètre carre | C15: M2 | D15: 4135 | G15: =+D15*E15 -> 0
A16: 11.2.2 | B16: Peinture Glycéro intérieur sur faux plafond hydrofuge
B17: Le mètre carre | C17: M2 | D17: 55 | G17: =+D17*E17 -> 0
A19: Total PEINTURE INTERIEURE | G19: =SUM(G15:G18) -> 0 | ZA19: STOT
B21: Montant HT du Lot N°11 PEINTURE | G21: =G19+G10 -> 0 | ZE21: TOTHT
B22: TVA (20%) | G22: =+G21*0.2 -> 0 | ZE22: TVA
B23: Montant TTC | G23: =SUM(G21:G22) -> 0 | ZE23: TOTTTC
